Workbook

Sheet 00_COVER
A1: Denmark: Digital Adoption and Policy Outcomes
A2: Statistical annex to Assessment 2 - Digital Policy and Innovation Report
A4: Student ID | B4: s4040040
A5: Course | B5: ECON1596/ECON1597 Digital Economy and Policy
A6: Assessment | B6: Assessment 2 - Digital Policy and Innovation Report
A7: Country | B7: Denmark (assigned by final digit of student ID: 0)
A8: Workbook version | B8: 1.0
A9: Built | B9: 2026-09-12
A10: Observations | B10: 113
A11: Coverage | B11: 1991-2026, unbalanced; see 07_LIMITATIONS
A13: Suggested citation | B13: Denmark: Digital Adoption and Policy Outcomes [data workbook], v1.0, 2026-09-12. Compiled from the sources listed in 03_SOURCES.
A15: Provenance rule | B15: Every value in this workbook was verified against the issuing authority named in its source_id. No value is interpolated, smoothed, or inferred from a neighbouring year. Gaps are left as gaps.
A16: Structure rule | B16: 02_MASTER is the single source of truth. Every figure sheet and every derived quantity is a formula view of it, not a pasted copy.
A18: CONTENTS
A19: 01_README | B19: Conventions, flag legend, how to trace any value
A20: 02_MASTER | B20: Every observation, one row each
A21: 03_SOURCES | B21: Source register with URLs, access dates, Harvard references
A22: 04_DEFINITIONS | B22: What each indicator measures, and what it excludes
A23: 05_CALC | B23: Derived quantities, as live formulas
A24: F1_BRANCHES | B24: Figure 1 - bank branch network, 2004-2024
A25: F2_PAYMENTS | B25: Figure 2 - payment instrument shares, 2017-2025
A26: F3_ESALES | B26: Figure 3 - e-sales share of turnover, DK vs EU
A27: F4_EXCLUSION | B27: Figure 4 - measures of digital exclusion
A28: F5_EU27 | B28: Figure 5 - online purchasing, all 27 member states, 2024
A29: F6_ADOPT_BENEFIT | B29: Figure 6 - adoption vs economic effect, EU 2024
A30: F7_QUALITY | B30: Figure 7 - DK vs EU: leads on adoption, trails on service quality
... A37: 08_AI_LOG | B37: AI use and validation log

Sheet 01_README
A1: How to read this workbook
A4: PURPOSE | B4: This workbook is the raw-data attachment to a 2,000-word policy report on Denmark's digital transformation. It is designed so that any number appearing in the report can be traced to an issuing authority, a denominator and an access date without consulting the author.
A5: TRACING A VALUE | B5: 1. Find the value on a figure sheet. 2. Read its series_code. 3. Filter 02_MASTER by that series_code to find the observation row. 4. Take its source_id to 03_SOURCES for the authority, URL and access date. 5. Check 04_DEFINITIONS for what the indicator does and does not cover.
A6: SINGLE SOURCE OF TRUTH | B6: 02_MASTER holds every observation. Figure sheets contain no typed numbers - each cell is a COUNTIFS/SUMIFS lookup against 02_MASTER. Correcting a value in 02_MASTER updates every sheet and chart that uses it.
A7: DENOMINATORS | B7: The denominator column in 02_MASTER is load-bearing, not decorative. Eurostat's Danish online-purchasing figures change base between 2019 (% of individuals) and 2020 onward (% of internet users). Series with different denominators are never plotted on one axis.
A9: FLAG LEGEND
A10: Flag | B10: Meaning
A11: b | B11: Break in series - definition or denominator changed. Do not plot across.
A12: e | B12: Estimate - source gives an approximation or a verbal quantity.
A13: p | B13: Provisional.
A14: d | B14: Definition differs from the rest of the series.
A15: u | B15: Low reliability.
A16: (blank) | B16: Value as published, no qualification.
A18: COLOUR LEGEND
B19: Retrieved value - as published by the source
B20: Derived - calculated by formula from retrieved values
B21: Flagged - estimate, break, or otherwise qualified
B22: Documented gap - value not retrieved
A25: BEFORE CITING | B25: Read 07_LIMITATIONS. Several series have very few observations and none supports inferential statistics.

Sheet 02_MASTER
A1: obs_id | B1: series_code | C1: indicator | D1: geo | E1: year | F1: value | G1: unit | H1: denominator | I1: flag | J1: source_id | K1: extraction_date | L1: notes
A2: 1 | B2: DK.PAY.CASH.POS | C2: Cash share of payments, physical retail | D2: DK | E2: 2017 | F2: 23 | G2: % | H2: share of number of payments in physical retail | J2: NB1 | K2: 2026-09-12
A3: 2 | B3: DK.PAY.CASH.POS | C3: Cash share of payments, physical retail | D3: DK | E3: 2023 | F3: 11 | G3: % | H3: share of number of payments in physical retail | J3: NB1 | K3: 2026-09-12
A4: 3 | B4: DK.PAY.CASH.POS | C4: Cash share of payments, physical retail | D4: DK | E4: 2025 | F4: 9 | G4: % | H4: share of number of payments in physical retail | J4: NB1 | K4: 2026-09-12
A5: 4 | B5: DK.PAY.CRD.PHYS | C5: Physical payment card share of payments | D5: DK | E5: 2017 | F5: 73 | G5: % | H5: share of number of payments in physical retail | J5: NB1 | K5: 2026-09-12
A6: 5 | B6: DK.PAY.CRD.PHYS | C6: Physical payment card share of payments | D6: DK | E6: 2025 | F6: 54 | G6: % | H6: share of number of payments in physical retail | J6: NB1 | K6: 2026-09-12
A7: 6 | B7: DK.PAY.WLT.SHR | C7: Mobile wallet share of payments | D7: DK | E7: 2025 | F7: 32 | G7: % | H7: share of number of payments in physical retail | J7: NB1 | K7: 2026-09-12 | L7: Card-based wallets on mobile phones (e.g. Apple Pay, Google Pay).
A8: 7 | B8: DK.PAY.DIG.POS.NUM | C8: Digital share of payments, by number | D8: DK | E8: 2025 | F8: 91 | G8: % | H8: share of number of payments in physical retail | J8: NB1 | K8: 2026-09-12
A9: 8 | B9: DK.PAY.DIG.POS.VAL | C9: Digital share of payments, by value | D9: DK | E9: 2025 | F9: 93 | G9: % | H9: share of value of payments in physical retail | J9: NB1 | K9: 2026-09-12 | L9: Different denominator from the by-number series - do not plot together.
A10: 9 | B10: DK.PAY.WLT.OWN | C10: Citizens holding a mobile wallet solution | D10: DK | E10: 2019 | F10: 12 | G10: % | H10: % of citizens | J10: NB1 | K10: 2026-09-12 | L10: Memo only - denominator differs from F2 series.
A11: 10 | B11: DK.PAY.WLT.OWN | C11: Citizens holding a mobile wallet solution | D11: DK | E11: 2023 | F11: 41 | G11: % | H11: % of citizens | J11: NB1 | K11: 2026-09-12 | L11: Memo only - denominator differs from F2 series.
A12: 11 | B12: DK.PAY.WLT.OWN | C12: Citizens holding a mobile wallet solution | D12: DK | E12: 2025 | F12: 51 | G12: % | H12: % of citizens | J12: NB1 | K12: 2026-09-12 | L12: Memo only - denominator differs from F2 series.
A13: 12 | B13: DK.FIN.BRCH | C13: Bank branches | D13: DK | E13: 2004 | F13: 2025 | G13: count | H13: branches | J13: FD1 | K13: 2026-09-12
A14: 13 | B14: DK.FIN.BRCH | C14: Bank branches | D14: DK | E14: 2006 | F14: 1975 | G14: count | H14: branches | J14: FD1 | K14: 2026-09-12
A15: 14 | B15: DK.FIN.BRCH | C15: Bank branches | D15: DK | E15: 2010 | F15: 1598 | G15: count | H15: branches | J15: FD1 | K15: 2026-09-12
A16: 15 | B16: DK.FIN.BRCH | C16: Bank branches | D16: DK | E16: 2016 | F16: 948 | G16: count | H16: branches | J16: FD1 | K16: 2026-09-12
A17: 16 | B17: DK.FIN.BRCH | C17: Bank branches | D17: DK | E17: 2021 | F17: 701 | G17: count | H17: branches | J17: FD1 | K17: 2026-09-12
A18: 17 | B18: DK.FIN.BRCH | C18: Bank branches | D18: DK | E18: 2024 | F18: 665 | G18: count | H18: branches | J18: FD1 | K18: 2026-09-12
A19: 18 | B19: DK.FIN.INST | C19: Financial institutions | D19: DK | E19: 1991 | F19: 219 | G19: count | H19: institutions | J19: FD1 | K19: 2026-09-12
A20: 19 | B20: DK.FIN.INST | C20: Financial institutions | D20: DK | E20: 2024 | F20: 51 | G20: count | H20: institutions | J20: FD1 | K20: 2026-09-12
A21: 20 | B21: DK.FIN.EMP | C21: Bank employees | D21: DK | E21: 1991 | F21: 51000 | G21: count | H21: persons employed | I21: e | J21: FD1 | K21: 2026-09-12 | L21: Source states 'around 51,000'.
A22: 21 | B22: DK.FIN.EMP | C22: Bank employees | D22: DK | E22: 2024 | F22: 36000 | G22: count | H22: persons employed | I22: e | J22: FD1 | K22: 2026-09-12 | L22: Source states 'just under 36,000'.
A23: 22 | B23: DK.ECM.IND.BUY | C23: Individuals who bought online in last 12 months | D23: DK | E23: 2019 | F23: 84 | G23: % | H23: % of individuals | I23: b | J23: ES1 | K23: 2026-09-12 | L23: BREAK: denominator is % of individuals. Highest in EU that year.
A24: 23 | B24: DK.ECM.IND.BUY | C24: Individuals who bought online in last 12 months | D24: DK | E24: 2020 | F24: 90 | G24: % | H24: % of internet users | J24: ES2 | K24: 2026-09-12 | L24: Rounded, from a Eurostat news release. Only the 2024 cross-section is available here unrounded, so this series mixes precisions across years.
A25: 24 | B25: DK.ECM.IND.BUY | C25: Individuals who bought online in last 12 months | D25: DK | E25: 2021 | F25: 92 | G25: % | H25: % of internet users | J25: ES3 | K25: 2026-09-12 | L25: Rounded, from a Eurostat news release. See the 2020 note on mixed precision.
A26: 25 | B26: EU.ECM.IND.BUY | C26: Individuals who bought online in last 12 months | D26: EU27 | E26: 2024 | F26: 76.58 | G26: % | H26: % of internet users | J26: ES7 | K26: 2026-09-12
A27: 26 | B27: AT.ECM.IND.BUY | C27: Individuals who bought online in last 12 months | D27: AT | E27: 2024 | F27: 74.18 | G27: % | H27: % of internet users | J27: ES7 | K27: 2026-09-12
A28: 27 | B28: BE.ECM.IND.BUY | C28: Individuals who bought online in last 12 months | D28: BE | E28: 2024 | F28: 78.98 | G28: % | H28: % of internet users | J28: ES7 | K28: 2026-09-12
A29: 28 | B29: BG.ECM.IND.BUY | C29: Individuals who bought online in last 12 months | D29: BG | E29: 2024 | F29: 57.18 | G29: % | H29: % of internet users | J29: ES7 | K29: 2026-09-12 | L29: Lowest of the 27, as the press release reported. Supersedes the rounded 57%.
A30: 29 | B30: CY.ECM.IND.BUY | C30: Individuals who bought online in last 12 months | D30: CY | E30: 2024 | F30: 68.16 | G30: % | H30: % of internet users | J30: ES7 | K30: 2026-09-12
A31: 30 | B31: CZ.ECM.IND.BUY | C31: Individuals who bought online in last 12 months | D31: CZ | E31: 2024 | F31: 86.21 | G31: % | H31: % of internet users | J31: ES7 | K31: 2026-09-12
A32: 31 | B32: DE.ECM.IND.BUY | C32: Individuals who bought online in last 12 months | D32: DE | E32: 2024 | F32: 82.53 | G32: % | H32: % of internet users | J32: ES7 | K32: 2026-09-12 | L32: Supersedes the rounded 83%.
A33: 32 | B33: DK.ECM.IND.BUY | C33: Individuals who bought online in last 12 months | D33: DK | E33: 2024 | F33: 90.86 | G33: % | H33: % of internet users | J33: ES7 | K33: 2026-09-12 | L33: Supersedes the rounded 91% taken from the Eurostat press release.
A34: 33 | B34: EE.ECM.IND.BUY | C34: Individuals who bought online in last 12 months | D34: EE | E34: 2024 | F34: 78.72 | G34: % | H34: % of internet users | J34: ES7 | K34: 2026-09-12
A35: 34 | B35: EL.ECM.IND.BUY | C35: Individuals who bought online in last 12 months | D35: EL | E35: 2024 | F35: 74.66 | G35: % | H35: % of internet users | J35: ES7 | K35: 2026-09-12
A36: 35 | B36: ES.ECM.IND.BUY | C36: Individuals who bought online in last 12 months | D36: ES | E36: 2024 | F36: 71.54 | G36: % | H36: % of internet users | J36: ES7 | K36: 2026-09-12
A37: 36 | B37: FI.ECM.IND.BUY | C37: Individuals who bought online in last 12 months | D37: FI | E37: 2024 | F37: 80.4 | G37: % | H37: % of internet users | J37: ES7 | K37: 2026-09-12
A38: 37 | B38: FR.ECM.IND.BUY | C38: Individuals who bought online in last 12 months | D38: FR | E38: 2024 | F38: 84.37 | G38: % | H38: % of internet users | J38: ES7 | K38: 2026-09-12
A39: 38 | B39: HR.ECM.IND.BUY | C39: Individuals who bought online in last 12 months | D39: HR | E39: 2024 | F39: 70.07 | G39: % | H39: % of internet users | J39: ES7 | K39: 2026-09-12
A40: 39 | B40: HU.ECM.IND.BUY | C40: Individuals who bought online in last 12 months | D40: HU | E40: 2024 | F40: 78.87 | G40: % | H40: % of internet users | J40: ES7 | K40: 2026-09-12 | L40: Supersedes the rounded 79%.
...

Sheet 03_SOURCES
A1: source_id | B1: authority | C1: publication | D1: dataset code | E1: URL | F1: accessed | G1: RMIT Harvard reference
A2: NB1 | B2: Danmarks Nationalbank | C2: Danskernes betalingsvaner | E2: https://www.nationalbanken.dk/en/what-we-do/safe-and-efficient-payments/payment-habits-in-denmark | F2: 2026-09-12 | G2: Danmarks Nationalbank 2025, Danskernes betalingsvaner, Danmarks Nationalbank, Copenhagen, accessed 12 September 2026, <https://www.nationalbanken.dk/en/what-we-do/safe-and-efficient-payments/payment-habits-in-denmark>.
A3: NB2 | B3: Danmarks Nationalbank | C3: [REFERENCE ONLY - supports argument in the report; no workbook value depends on it] Danskerne betaler mere digitalt - det goer offline-betalinger endnu vigtigere som beredskab (press release, 26 June 2026) | E3: https://www.nationalbanken.dk/da/viden-og-nyheder/presse/arkiv/2026/danskerne-betaler-mere-digitalt-det-goer-offline-betalinger-endnu-vigtigere-som-beredskab-26-06-2026 | F3: 2026-09-12 | G3: Danmarks Nationalbank 2026, Danskerne betaler mere digitalt - det goer offline-betalinger endnu vigtigere som beredskab, press release, 26 June, Danmarks Nationalbank, Copenhagen, accessed 12 September 2026.
A4: FD1 | B4: Finans Danmark | C4: Institutter, filialer & ansatte | E4: https://finansdanmark.dk/tal-og-data/institutter-filialer-ansatte/ | F4: 2026-09-12 | G4: Finans Danmark 2025, Institutter, filialer & ansatte, Finans Danmark, Copenhagen, accessed 12 September 2026, <https://finansdanmark.dk/tal-og-data/institutter-filialer-ansatte/>.
A5: ES1 | B5: Eurostat | C5: E-commerce statistics for individuals (Statistics Explained) | D5: isoc_ec_ib20 / isoc_ec_ibuy | E5: https://ec.europa.eu/eurostat/statistics-explained/index.php?title=E-commerce_statistics_for_individuals | F5: 2026-09-12 | G5: Eurostat 2025, E-commerce statistics for individuals, Statistics Explained, European Commission, Luxembourg, accessed 12 September 2026.
A6: ES2 | B6: Eurostat | C6: Online shopping ever more popular in 2020 (ddn-20210217-1) | D6: isoc_ec_ib20 | E6: https://ec.europa.eu/eurostat/web/products-eurostat-news/-/ddn-20210217-1 | F6: 2026-09-12 | G6: Eurostat 2021, Online shopping ever more popular in 2020, European Commission, Luxembourg, accessed 12 September 2026.
A7: ES3 | B7: Eurostat | C7: Online shopping ever more popular (ddn-20220202-1) | D7: isoc_ec_ib20 | E7: https://ec.europa.eu/eurostat/web/products-eurostat-news/-/ddn-20220202-1 | F7: 2026-09-12 | G7: Eurostat 2022, Online shopping ever more popular, European Commission, Luxembourg, accessed 12 September 2026.
A8: ES4 | B8: Eurostat | C8: E-commerce statistics for individuals, 2024 reference year (ddn-20250220-3) | D8: isoc_ec_ib20 | E8: https://ec.europa.eu/eurostat/web/products-eurostat-news/w/ddn-20250220-3 | F8: 2026-09-12 | G8: Eurostat 2025, E-commerce statistics for individuals, European Commission, Luxembourg, accessed 12 September 2026.
A9: ES5 | B9: Eurostat | C9: EU enterprises' online sales reach new heights in 2023 (ddn-20250227-2) | D9: isoc_ec_evaln2 / tin00110 | E9: https://ec.europa.eu/eurostat/web/products-eurostat-news/w/ddn-20250227-2 | F9: 2026-09-12 | G9: Eurostat 2025, EU enterprises' online sales reach new heights, European Commission, Luxembourg, accessed 12 September 2026.
A10: ES6 | B10: Eurostat | C10: Share of enterprises' turnover on e-commerce, by country (country-level values retrieved via search of the Eurostat indicator) | D10: tin00110 | E10: https://ec.europa.eu/eurostat/databrowser/view/tin00110/default/table?lang=en | F10: 2026-09-12 | G10: Eurostat 2025, Share of enterprises' turnover on e-commerce (tin00110), European Commission, Luxembourg, accessed 12 September 2026.
A11: EC1 | B11: European Commission | C11: Digital Decade 2026 country report: Denmark, SWD(2026) 155 final, Part 7/27, 17 June 2026 | D11: DESI 2026 | E11: https://digital-strategy.ec.europa.eu/en/policies/desi | F11: 2026-09-12 | G11: European Commission 2026, Digital Decade 2026 country report: Denmark, SWD(2026) 155 final, Part 7/27, European Commission, Brussels.
A12: DG1 | B12: Digitaliseringsstyrelsen (Danish Agency for Digital Government) | C12: Statistik om Digital Post | E12: https://digst.dk/tal-og-statistik/ | F12: 2026-09-12 | G12: Digitaliseringsstyrelsen 2026, Statistik om Digital Post, Agency for Digital Government, Copenhagen, accessed 12 September 2026.
A13: DG2 | B13: Digitaliseringsstyrelsen (Danish Agency for Digital Government) | C13: Hvem oplever udfordringer ved det digitale? | E13: https://digst.dk/digital-inklusion/viden-om-digital-inklusion/hvem-oplever-udfordringer-ved-det-digitale/ | F13: 2026-09-12 | G13: Digitaliseringsstyrelsen 2025, Hvem oplever udfordringer ved det digitale?, Agency for Digital Government, Copenhagen, accessed 12 September 2026.
A14: DG3 | B14: Digitaliseringsstyrelsen / Danmarks Statistik | C14: Effektmaaling af SMV:Digital, June 2025 | E14: https://digst.dk/media/yz2ouzzz/effektmaaling-af-smvdigital-2025.pdf | F14: 2026-09-12 | G14: Digitaliseringsstyrelsen 2025, Effektmaaling af SMV:Digital, prepared by Danmarks Statistik, Agency for Digital Government, Copenhagen, accessed 12 September 2026.
A15: JU1 | B15: Justitia (independent Danish legal think tank) | C15: Retssikkerhed for digitalt udsatte borgere, July 2022 | D15: Folketinget DIU Alm.del bilag 32 | E15: https://justitia-int.org/wp-content/uploads/2022/09/Rapport_Retssikkerhed-for-digitalt-udsatte-borgere-1.pdf | F15: 2026-09-12 | G15: Justitia 2022, Retssikkerhed for digitalt udsatte borgere, Justitia, Copenhagen, accessed 12 September 2026.
A16: IMR1 | B16: Institut for Menneskerettigheder (Danish Institute for Human Rights) | C16: [REFERENCE ONLY - supports argument in the report; no workbook value depends on it] Rettigheder i den digitale velfaerdsstat, December 2023 | E16: https://menneskeret.dk/sites/menneskeret.dk/files/media/document/Rettigheder%20i%20den%20digitale%20velf%C3%A6rdsstat.%20Analyse,%20Institut%20for%20Menneskerettigheder,%20december%202023.PDF | F16: 2026-09-12 | G16: Institut for Menneskerettigheder 2023, Rettigheder i den digitale velfaerdsstat, Danish Institute for Human Rights, Copenhagen, accessed 12 September 2026.
A17: RI1 | B17: Retsinformation (Danish official legal information portal) | C17: Lov om Offentlig Digital Post, LOV nr 528 af 11/06/2012 | D17: ELI: lta/2012/528 | E17: https://www.retsinformation.dk/eli/lta/2012/528 | F17: 2026-09-12 | G17: Denmark 2012, Lov om Offentlig Digital Post (LOV nr 528 af 11/06/2012), Retsinformation, Copenhagen, accessed 12 September 2026.
A18: RR1 | B18: Rigsrevisionen (Danish National Audit Office) | C18: Beretning om besparelsespotentialet ved obligatorisk Digital Post paa ca. 1 mia. kr. om aaret, January 2016 | E18: https://www.rigsrevisionen.dk/revisionssager-arkiv/2016/jan/beretning-om-besparelsespotentialet-ved-obligatorisk-digital-post-paa-ca-1-mia-kr-om-aaret | F18: 2026-09-12 | G18: Rigsrevisionen 2016, Beretning om besparelsespotentialet ved obligatorisk Digital Post paa ca. 1 mia. kr. om aaret, National Audit Office of Denmark, Copenhagen, accessed 12 September 2026.
A19: RI2 | B19: Finanstilsynet (Danish Financial Supervisory Authority) | C19: Kontantreglen - lov om betalinger section 81 | D19: Lov om betalinger, ss 81 | E19: https://www.finanstilsynet.dk/finansielle-temaer/betalingstjenester-og-e-penge/kontantreglen | F19: 2026-09-12 | G19: Finanstilsynet 2025, Kontantreglen, Danish Financial Supervisory Authority, Copenhagen, accessed 12 September 2026.
A20: DG4 | B20: Digitaliseringsstyrelsen (Danish Agency for Digital Government) | C20: Digital Post - lovgivning, and the MitID transition news archive | E20: https://digst.dk/it-loesninger/digital-post/lovgivning/ | F20: 2026-09-12 | G20: Digitaliseringsstyrelsen 2025, Digital Post - lovgivning, Agency for Digital Government, Copenhagen, accessed 12 September 2026.
A21: SMV1 | B21: SMV:Digital (Danish SME digitalisation grant scheme) | C21: Tilskudspuljer i 2026 | E21: https://smvdigital.dk/content/ydelser/tilskudspuljer-i-2026/8efa07f4-5032-47f4-b7fa-bab57412b762/ | F21: 2026-09-12 | G21: SMV:Digital 2026, Tilskudspuljer i 2026, SMV:Digital, Copenhagen, accessed 12 September 2026.
A22: DST2 | B22: Danmarks Statistik | C22: Befolkningstal (population figures) | D22: StatBank FOLK1A | E22: https://www.dst.dk/da/Statistik/emner/borgere/befolkning/befolkningstal | F22: 2026-09-12 | G22: Danmarks Statistik 2026, Befolkningstal, Statistics Denmark, Copenhagen, accessed 12 September 2026.
A23: ES7 | B23: Eurostat | C23: Internet purchases by individuals (2020 onwards) - custom extraction, all individuals, last online purchase in the 12 months, percentage of individuals who used internet within the last year, 2024 | D23: isoc_ec_ib20 | E23: https://ec.europa.eu/eurostat/databrowser/view/isoc_ec_ib20/default/table?lang=en | F23: 2026-09-12 | G23: Eurostat 2026, Internet purchases by individuals (2020 onwards), dataset isoc_ec_ib20, Statistical Office of the European Union, Luxembourg, data last updated 17 April 2026, accessed 12 September 2026, <https://ec.europa.eu/eurostat/databrowser/view/isoc_ec_ib20/default/table?lang=en>.
A24: DST1 | B24: Danmarks Statistik | C24: Detailomsaetningsindeks (retail trade turnover index) | D24: StatBank; base year rebased 2015 -> 2021 | E24: https://www.dst.dk/da/Statistik/dokumentation/statistikdokumentation/detailomsaetningsindeks | F24: 2026-09-12 | G24: Danmarks Statistik 2025, Detailomsaetningsindeks, Statistics Denmark, Copenhagen, accessed 12 September 2026.

Sheet 04_DEFINITIONS
A1: series_code | B1: what it measures | C1: what it excludes / watch for
A2: PREFIXES: definitions below are written against the DK.* codes. The same definition applies to the identical indicator for any other geography - EU.*, and the member-state codes AT.* through SE.* used in F5_EU27 and F6_ADOPT_BENEFIT. Only the geography changes; the measure and its denominator do not.
A3: DK.PAY.CASH.POS | B3: Cash as a share of the NUMBER of payments made at physical points of sale. | C3: Not a share of value. Excludes e-commerce entirely.
A4: DK.PAY.CRD.PHYS | B4: Physical payment cards as a share of the number of in-store payments. | C4: Falls partly because wallets replace the physical card, not because card payment declines.
A5: DK.PAY.WLT.SHR | B5: Card-based mobile wallets as a share of the number of in-store payments. | C5: Wallet payments are card payments. Do not add to the card share.
A6: DK.PAY.WLT.OWN | B6: Share of CITIZENS with a wallet solution on their phone. | C6: Different denominator from the payment-share series. Memo only - deliberately excluded from Figure 2.
A7: DK.FIN.BRCH | B7: Number of retail bank branches operated by Danish credit institutions. | C7: Consolidation and digitalisation both reduce this. The series alone cannot separate the two causes.
A8: DK.ECM.IND.BUY | B8: Individuals who purchased goods or services online in the last 12 months. | C8: DENOMINATOR BREAK at 2020: % of individuals before, % of internet users after. Never plot 2019 with later years.
A9: DK.ECM.ENT.TRN | B9: E-commerce sales as a share of total enterprise turnover. | C9: Measures INTENSITY of online selling, not how many firms sell online. Pair with DK.ECM.ENT.SHR.
A10: DK.ECM.ENT.SHR | B10: Share of enterprises making any e-sales. | C10: Measures BREADTH of adoption. Flat breadth with rising intensity means incumbents deepening, not new entrants.
A11: DK.DGP.EXMP | B11: Citizens formally exempt from mandatory Digital Post under the statutory exemption regime. | C11: An administrative status, not a measure of capability. A citizen may struggle without being exempt.
A12: DK.DGX.DIFF | B12: Population estimated to face difficulties using digital public services. | C12: A capability estimate, not an administrative count. Much larger than the exemption rate - that gap is the analytical point.
A13: DK.DGX.JUST | B13: Justitia's estimate of the digitally disadvantaged adult population. | C13: Think-tank estimate, broadest definition of the five. Cite as an upper bound, not as an official statistic.
A14: DK.GOV.DPS.CIT | B14: eGovernment Benchmark composite score for citizen-facing digital public services. | C14: A composite index, not a usage rate. Denmark scores BELOW the EU average despite near-universal mandated use.
... A31: DK.SME.SMVD.PROJ, DK.SME.SMVD.INV, DK.SME.SMVD.NOINV | B31: SMV:Digital programme: projects supported, and participants who did or did not invest further. | C31: Self-reported by participants, with no control group. Cannot support a causal claim about the programme - see the withdrawn claim in 07_LIMITATIONS and 08_AI_LOG.

Sheet 05_CALC
A1: Derived quantities
A2: Every cell below is a live formula over 02_MASTER. No pasted numbers.
A4: quantity | B4: formula result | C4: unit | D4: how it is built
A5: Bank branches, 2004 | B5: =IF(COUNTIFS('02_MASTER'!$B:$B,"DK.FIN.BRCH",'02_MASTER'!$E:$E,2004)=0,"",SUMIFS('02_MASTER'!$F:$F,'02_MASTER'!$B:$B,"DK.FIN.BRCH",'02_MASTER'!$E:$E,2004)) | C5: count | D5: Direct lookup from 02_MASTER.
A6: Bank branches, 2024 | B6: =IF(COUNTIFS('02_MASTER'!$B:$B,"DK.FIN.BRCH",'02_MASTER'!$E:$E,2024)=0,"",SUMIFS('02_MASTER'!$F:$F,'02_MASTER'!$B:$B,"DK.FIN.BRCH",'02_MASTER'!$E:$E,2024)) | C6: count | D6: Direct lookup from 02_MASTER.
A7: Branch network change, 2004-2024 | B7: =(IF(COUNTIFS('02_MASTER'!$B:$B,"DK.FIN.BRCH",'02_MASTER'!$E:$E,2024)=0,"",SUMIFS('02_MASTER'!$F:$F,'02_MASTER'!$B:$B,"DK.FIN.BRCH",'02_MASTER'!$E:$E,2024))/IF(COUNTIFS('02_MASTER'!$B:$B,"DK.FIN.BRCH",'02_MASTER'!$E:$E,2004)=0,"",SUMIFS('02_MASTER'!$F:$F,'02_MASTER'!$B:$B,"DK.FIN.BRCH",'02_MASTER'!$E:$E,2004)))-1 | C7: % | D7: Headline structural change for Figure 1.
A8: Cash share change, 2017-2025 | B8: =IF(COUNTIFS('02_MASTER'!$B:$B,"DK.PAY.CASH.POS",'02_MASTER'!$E:$E,2025)=0,"",SUMIFS('02_MASTER'!$F:$F,'02_MASTER'!$B:$B,"DK.PAY.CASH.POS",'02_MASTER'!$E:$E,2025))-IF(COUNTIFS('02_MASTER'!$B:$B,"DK.PAY.CASH.POS",'02_MASTER'!$E:$E,2017)=0,"",SUMIFS('02_MASTER'!$F:$F,'02_MASTER'!$B:$B,"DK.PAY.CASH.POS",'02_MASTER'!$E:$E,2017)) | C8: pp | D8: Percentage-point change, not a growth rate - both terms are shares.
A9: Cash share, proportional decline 2017-2025 | B9: =(IF(COUNTIFS('02_MASTER'!$B:$B,"DK.PAY.CASH.POS",'02_MASTER'!$E:$E,2025)=0,"",SUMIFS('02_MASTER'!$F:$F,'02_MASTER'!$B:$B,"DK.PAY.CASH.POS",'02_MASTER'!$E:$E,2025))/IF(COUNTIFS('02_MASTER'!$B:$B,"DK.PAY.CASH.POS",'02_MASTER'!$E:$E,2017)=0,"",SUMIFS('02_MASTER'!$F:$F,'02_MASTER'!$B:$B,"DK.PAY.CASH.POS",'02_MASTER'!$E:$E,2017)))-1 | C9: % | D9: Cash fell to roughly a third of its 2017 share.
A10: DK e-sales turnover share, change 2014-2024 | B10: =(IF(COUNTIFS('02_MASTER'!$B:$B,"DK.ECM.ENT.TRN",'02_MASTER'!$E:$E,2024)=0,"",SUMIFS('02_MASTER'!$F:$F,'02_MASTER'!$B:$B,"DK.ECM.ENT.TRN",'02_MASTER'!$E:$E,2024))/IF(COUNTIFS('02_MASTER'!$B:$B,"DK.ECM.ENT.TRN",'02_MASTER'!$E:$E,2014)=0,"",SUMIFS('02_MASTER'!$F:$F,'02_MASTER'!$B:$B,"DK.ECM.ENT.TRN",'02_MASTER'!$E:$E,2014)))-1 | C10: % | D10: Tests the 'enterprise plateau' claim. Intensity nearly doubled.
A11: EU e-sales turnover share, change 2014-2024 | B11: =(IF(COUNTIFS('02_MASTER'!$B:$B,"EU.ECM.ENT.TRN",'02_MASTER'!$E:$E,2024)=0,"",SUMIFS('02_MASTER'!$F:$F,'02_MASTER'!$B:$B,"EU.ECM.ENT.TRN",'02_MASTER'!$E:$E,2024))/IF(COUNTIFS('02_MASTER'!$B:$B,"EU.ECM.ENT.TRN",'02_MASTER'!$E:$E,2014)=0,"",SUMIFS('02_MASTER'!$F:$F,'02_MASTER'!$B:$B,"EU.ECM.ENT.TRN",'02_MASTER'!$E:$E,2014)))-1 | C11: % | D11: Comparator for the line above.
A12: DK lead over EU on e-sales turnover, 2024 | B12: =IF(COUNTIFS('02_MASTER'!$B:$B,"DK.ECM.ENT.TRN",'02_MASTER'!$E:$E,2024)=0,"",SUMIFS('02_MASTER'!$F:$F,'02_MASTER'!$B:$B,"DK.ECM.ENT.TRN",'02_MASTER'!$E:$E,2024))-IF(COUNTIFS('02_MASTER'!$B:$B,"EU.ECM.ENT.TRN",'02_MASTER'!$E:$E,2024)=0,"",SUMIFS('02_MASTER'!$F:$F,'02_MASTER'!$B:$B,"EU.ECM.ENT.TRN",'02_MASTER'!$E:$E,2024)) | C12: pp | D12: Denmark's margin over the EU average.
A13: Exclusion ratio: difficulty vs formal exemption | B13: =IF(COUNTIFS('02_MASTER'!$B:$B,"DK.DGX.DIFF",'02_MASTER'!$E:$E,2026)=0,"",SUMIFS('02_MASTER'!$F:$F,'02_MASTER'!$B:$B,"DK.DGX.DIFF",'02_MASTER'!$E:$E,2026))/IF(COUNTIFS('02_MASTER'!$B:$B,"DK.DGP.EXMP",'02_MASTER'!$E:$E,2026)=0,"",SUMIFS('02_MASTER'!$F:$F,'02_MASTER'!$B:$B,"DK.DGP.EXMP",'02_MASTER'!$E:$E,2026)) | C13: ratio | D13: How many times larger the capability measure is than the administrative one. The core Q4 statistic.
A14: Citizens struggling but NOT exempt | B14: =IF(COUNTIFS('02_MASTER'!$B:$B,"DK.DGX.DIFF",'02_MASTER'!$E:$E,2026)=0,"",SUMIFS('02_MASTER'!$F:$F,'02_MASTER'!$B:$B,"DK.DGX.DIFF",'02_MASTER'!$E:$E,2026))-IF(COUNTIFS('02_MASTER'!$B:$B,"DK.DGP.EXMP",'02_MASTER'!$E:$E,2026)=0,"",SUMIFS('02_MASTER'!$F:$F,'02_MASTER'!$B:$B,"DK.DGP.EXMP",'02_MASTER'!$E:$E,2026)) | C14: pp | D14: Population facing difficulty without statutory relief.
A15: Digital skills gap, 16-24 vs 55-74 | B15: =IF(COUNTIFS('02_MASTER'!$B:$B,"DK.SKL.1624",'02_MASTER'!$E:$E,2025)=0,"",SUMIFS('02_MASTER'!$F:$F,'02_MASTER'!$B:$B,"DK.SKL.1624",'02_MASTER'!$E:$E,2025))-IF(COUNTIFS('02_MASTER'!$B:$B,"DK.SKL.5574",'02_MASTER'!$E:$E,2025)=0,"",SUMIFS('02_MASTER'!$F:$F,'02_MASTER'!$B:$B,"DK.SKL.5574",'02_MASTER'!$E:$E,2025)) | C15: pp | D15: Generational gradient in basic digital skills.
A16: AI adoption gap, large firms vs SMEs | B16: =IF(COUNTIFS('02_MASTER'!$B:$B,"DK.ENT.AI.LRG",'02_MASTER'!$E:$E,2025)=0,"",SUMIFS('02_MASTER'!$F:$F,'02_MASTER'!$B:$B,"DK.ENT.AI.LRG",'02_MASTER'!$E:$E,2025))-IF(COUNTIFS('02_MASTER'!$B:$B,"DK.ENT.AI.SME",'02_MASTER'!$E:$E,2025)=0,"",SUMIFS('02_MASTER'!$F:$F,'02_MASTER'!$B:$B,"DK.ENT.AI.SME",'02_MASTER'!$E:$E,2025)) | C16: pp | D16: Depth-of-adoption gap behind the 'breadth without depth' finding.
A17: DK shortfall vs EU, citizen digital public services | B17: =IF(COUNTIFS('02_MASTER'!$B:$B,"DK.GOV.DPS.CIT",'02_MASTER'!$E:$E,2025)=0,"",SUMIFS('02_MASTER'!$F:$F,'02_MASTER'!$B:$B,"DK.GOV.DPS.CIT",'02_MASTER'!$E:$E,2025))-IF(COUNTIFS('02_MASTER'!$B:$B,"EU.GOV.DPS.CIT",'02_MASTER'!$E:$E,2025)=0,"",SUMIFS('02_MASTER'!$F:$F,'02_MASTER'!$B:$B,"EU.GOV.DPS.CIT",'02_MASTER'!$E:$E,2025)) | C17: points | D17: Negative: Denmark scores below the EU average.
A18: DK shortfall vs EU, ICT waste recycling | B18: =IF(COUNTIFS('02_MASTER'!$B:$B,"DK.ENV.WEEE",'02_MASTER'!$E:$E,2023)=0,"",SUMIFS('02_MASTER'!$F:$F,'02_MASTER'!$B:$B,"DK.ENV.WEEE",'02_MASTER'!$E:$E,2023))-IF(COUNTIFS('02_MASTER'!$B:$B,"EU.ENV.WEEE",'02_MASTER'!$E:$E,2023)=0,"",SUMIFS('02_MASTER'!$F:$F,'02_MASTER'!$B:$B,"EU.ENV.WEEE",'02_MASTER'!$E:$E,2023)) | C18: pp | D18: Negative and large - candidate SDG evidence.
A19: Trust in digital public solutions, change 2024-2025 | B19: =IF(COUNTIFS('02_MASTER'!$B:$B,"DK.TRU.DPS",'02_MASTER'!$E:$E,2025)=0,"",SUMIFS('02_MASTER'!$F:$F,'02_MASTER'!$B:$B,"DK.TRU.DPS",'02_MASTER'!$E:$E,2025))-IF(COUNTIFS('02_MASTER'!$B:$B,"DK.TRU.DPS",'02_MASTER'!$E:$E,2024)=0,"",SUMIFS('02_MASTER'!$F:$F,'02_MASTER'!$B:$B,"DK.TRU.DPS",'02_MASTER'!$E:$E,2024)) | C19: pp | D19: Trust rising while the mandate is in force.
A20: Perceived security of Digital Post, change 2017-2025 | B20: =IF(COUNTIFS('02_MASTER'!$B:$B,"DK.TRU.DGP.SEC",'02_MASTER'!$E:$E,2025)=0,"",SUMIFS('02_MASTER'!$F:$F,'02_MASTER'!$B:$B,"DK.TRU.DGP.SEC",'02_MASTER'!$E:$E,2025))-IF(COUNTIFS('02_MASTER'!$B:$B,"DK.TRU.DGP.SEC",'02_MASTER'!$E:$E,2017)=0,"",SUMIFS('02_MASTER'!$F:$F,'02_MASTER'!$B:$B,"DK.TRU.DGP.SEC",'02_MASTER'!$E:$E,2017)) | C20: pp | D20: Trust in the mandated system over the mandate period (CLO4).
A21: Digital Post: projected annual saving | B21: =IF(COUNTIFS('02_MASTER'!$B:$B,"DK.GOV.DGP.SAVE.PLAN",'02_MASTER'!$E:$E,2016)=0,"",SUMIFS('02_MASTER'!$F:$F,'02_MASTER'!$B:$B,"DK.GOV.DGP.SAVE.PLAN",'02_MASTER'!$E:$E,2016)) | C21: mDKK/yr | D21: Ministry of Finance business case for the mandate (RR1).
A22: Digital Post: saving verifiable by audit | B22: =IF(COUNTIFS('02_MASTER'!$B:$B,"DK.GOV.DGP.SAVE.VERIF",'02_MASTER'!$E:$E,2016)=0,"",SUMIFS('02_MASTER'!$F:$F,'02_MASTER'!$B:$B,"DK.GOV.DGP.SAVE.VERIF",'02_MASTER'!$E:$E,2016)) | C22: mDKK/yr | D22: Postage, paper and envelopes only (RR1).
A23: Digital Post: unverified share of the business case | B23: =1-(IF(COUNTIFS('02_MASTER'!$B:$B,"DK.GOV.DGP.SAVE.VERIF",'02_MASTER'!$E:$E,2016)=0,"",SUMIFS('02_MASTER'!$F:$F,'02_MASTER'!$B:$B,"DK.GOV.DGP.SAVE.VERIF",'02_MASTER'!$E:$E,2016))/IF(COUNTIFS('02_MASTER'!$B:$B,"DK.GOV.DGP.SAVE.PLAN",'02_MASTER'!$E:$E,2016)=0,"",SUMIFS('02_MASTER'!$F:$F,'02_MASTER'!$B:$B,"DK.GOV.DGP.SAVE.PLAN",'02_MASTER'!$E:$E,2016))) | C23: % | D23: Over half the projected saving - the wage and overhead component - was never substantiated. The cross-government study intended to test it was abandoned. The strongest cost-side finding in this workbook.
A24: Digital Post: cost per formally exempt citizen, if the shortfall is real | B24: =((IF(COUNTIFS('02_MASTER'!$B:$B,"DK.GOV.DGP.SAVE.PLAN",'02_MASTER'!$E:$E,2016)=0,"",SUMIFS('02_MASTER'!$F:$F,'02_MASTER'!$B:$B,"DK.GOV.DGP.SAVE.PLAN",'02_MASTER'!$E:$E,2016))-IF(COUNTIFS('02_MASTER'!$B:$B,"DK.GOV.DGP.SAVE.VERIF",'02_MASTER'!$E:$E,2016)=0,"",SUMIFS('02_MASTER'!$F:$F,'02_MASTER'!$B:$B,"DK.GOV.DGP.SAVE.VERIF",'02_MASTER'!$E:$E,2016)))*1000000)/IF(COUNTIFS('02_MASTER'!$B:$B,"DK.DGP.EXMP.N",'02_MASTER'!$E:$E,2026)=0,"",SUMIFS('02_MASTER'!$F:$F,'02_MASTER'!$B:$B,"DK.DGP.EXMP.N",'02_MASTER'!$E:$E,2026)) | C24: DKK | D24: ILLUSTRATIVE ONLY, and not a real unit cost: it divides an unverified saving shortfall by an unrelated headcount. Included because the comparison of magnitudes is informative; it must not be quoted as a cost per person.
A25: Resident population, 1 January 2026 | B25: =IF(COUNTIFS('02_MASTER'!$B:$B,"DK.POP.TOT",'02_MASTER'!$E:$E,2026)=0,"",SUMIFS('02_MASTER'!$F:$F,'02_MASTER'!$B:$B,"DK.POP.TOT",'02_MASTER'!$E:$E,2026)) | C25: count | D25: Direct lookup. The only population level in the workbook (DST2).
A26: Citizens formally exempt from Digital Post, Q1 2026 | B26: =IF(COUNTIFS('02_MASTER'!$B:$B,"DK.DGP.EXMP.N",'02_MASTER'!$E:$E,2026)=0,"",SUMIFS('02_MASTER'!$F:$F,'02_MASTER'!$B:$B,"DK.DGP.EXMP.N",'02_MASTER'!$E:$E,2026)) | C26: count | D26: Headcount behind the 4.7% rate (DG1).
A27: Change in exempt headcount, 2025 to 2026 | B27: =IF(COUNTIFS('02_MASTER'!$B:$B,"DK.DGP.EXMP.N",'02_MASTER'!$E:$E,2026)=0,"",SUMIFS('02_MASTER'!$F:$F,'02_MASTER'!$B:$B,"DK.DGP.EXMP.N",'02_MASTER'!$E:$E,2026))-IF(COUNTIFS('02_MASTER'!$B:$B,"DK.DGP.EXMP.N",'02_MASTER'!$E:$E,2025)=0,"",SUMIFS('02_MASTER'!$F:$F,'02_MASTER'!$B:$B,"DK.DGP.EXMP.N",'02_MASTER'!$E:$E,2025)) | C27: count | D27: Falling. Note the 2025 figure is an 'approximately' value, so this difference is not precise.

Sheet F1_BRANCHES
A1: Figure 1 - Denmark's bank branch network, 2004-2024
A2: Series DK.FIN.BRCH. Values are formula lookups from 02_MASTER.
D3: Bank branches in Denmark, 2004-2024
A4: year | B4: bank branches | D4: Count of retail branches. Uneven year spacing, numeric X axis.
A5: 2004 | B5: =IF(COUNTIFS('02_MASTER'!$B:$B,"DK.FIN.BRCH",'02_MASTER'!$E:$E,2004)=0,"",SUMIFS('02_MASTER'!$F:$F,'02_MASTER'!$B:$B,"DK.FIN.BRCH",'02_MASTER'!$E:$E,2004))
A6: 2006 | B6: =IF(COUNTIFS('02_MASTER'!$B:$B,"DK.FIN.BRCH",'02_MASTER'!$E:$E,2006)=0,"",SUMIFS('02_MASTER'!$F:$F,'02_MASTER'!$B:$B,"DK.FIN.BRCH",'02_MASTER'!$E:$E,2006))
A7: 2010 | B7: =IF(COUNTIFS('02_MASTER'!$B:$B,"DK.FIN.BRCH",'02_MASTER'!$E:$E,2010)=0,"",SUMIFS('02_MASTER'!$F:$F,'02_MASTER'!$B:$B,"DK.FIN.BRCH",'02_MASTER'!$E:$E,2010))
A8: 2016 | B8: =IF(COUNTIFS('02_MASTER'!$B:$B,"DK.FIN.BRCH",'02_MASTER'!$E:$E,2016)=0,"",SUMIFS('02_MASTER'!$F:$F,'02_MASTER'!$B:$B,"DK.FIN.BRCH",'02_MASTER'!$E:$E,2016))
A9: 2021 | B9: =IF(COUNTIFS('02_MASTER'!$B:$B,"DK.FIN.BRCH",'02_MASTER'!$E:$E,2021)=0,"",SUMIFS('02_MASTER'!$F:$F,'02_MASTER'!$B:$B,"DK.FIN.BRCH",'02_MASTER'!$E:$E,2021))
A10: 2024 | B10: =IF(COUNTIFS('02_MASTER'!$B:$B,"DK.FIN.BRCH",'02_MASTER'!$E:$E,2024)=0,"",SUMIFS('02_MASTER'!$F:$F,'02_MASTER'!$B:$B,"DK.FIN.BRCH",'02_MASTER'!$E:$E,2024))
A12: Source: Finans Danmark, Institutter, filialer & ansatte (FD1). Note: years are unevenly spaced, so the chart uses a numeric X axis - a category axis would imply a constant rate of decline that the data does not show.

Sheet F2_PAYMENTS
A1: Figure 2 - Cash displacement in Danish physical retail
A2: Denominator throughout: share of the NUMBER of in-store payments.
A4: Panel A - Cash share of in-store payments | D4: Cash share of in-store payments, 2017-2025
A5: year | B5: cash (%) | D5: % of the number of payments made in physical retail.
A6: 2017 | B6: =IF(COUNTIFS('02_MASTER'!$B:$B,"DK.PAY.CASH.POS",'02_MASTER'!$E:$E,2017)=0,"",SUMIFS('02_MASTER'!$F:$F,'02_MASTER'!$B:$B,"DK.PAY.CASH.POS",'02_MASTER'!$E:$E,2017))
A7: 2023 | B7: =IF(COUNTIFS('02_MASTER'!$B:$B,"DK.PAY.CASH.POS",'02_MASTER'!$E:$E,2023)=0,"",SUMIFS('02_MASTER'!$F:$F,'02_MASTER'!$B:$B,"DK.PAY.CASH.POS",'02_MASTER'!$E:$E,2023))
A8: 2025 | B8: =IF(COUNTIFS('02_MASTER'!$B:$B,"DK.PAY.CASH.POS",'02_MASTER'!$E:$E,2025)=0,"",SUMIFS('02_MASTER'!$F:$F,'02_MASTER'!$B:$B,"DK.PAY.CASH.POS",'02_MASTER'!$E:$E,2025))
A10: Panel B - Composition of in-store payments, 2025 | D10: Composition of in-store payments, 2025
A11: instrument | B11: share of payments (%) | D11: Sums to 95%; the residual is other digital instruments.
A12: Physical payment card | B12: =IF(COUNTIFS('02_MASTER'!$B:$B,"DK.PAY.CRD.PHYS",'02_MASTER'!$E:$E,2025)=0,"",SUMIFS('02_MASTER'!$F:$F,'02_MASTER'!$B:$B,"DK.PAY.CRD.PHYS",'02_MASTER'!$E:$E,2025))
A13: Mobile wallet (card-based) | B13: =IF(COUNTIFS('02_MASTER'!$B:$B,"DK.PAY.WLT.SHR",'02_MASTER'!$E:$E,2025)=0,"",SUMIFS('02_MASTER'!$F:$F,'02_MASTER'!$B:$B,"DK.PAY.WLT.SHR",'02_MASTER'!$E:$E,2025))
A14: Cash | B14: =IF(COUNTIFS('02_MASTER'!$B:$B,"DK.PAY.CASH.POS",'02_MASTER'!$E:$E,2025)=0,"",SUMIFS('02_MASTER'!$F:$F,'02_MASTER'!$B:$B,"DK.PAY.CASH.POS",'02_MASTER'!$E:$E,2025))
A16: MEMO - different denominator, not charted above
A17: year | B17: citizens holding a mobile wallet (%)
A18: 2019 | B18: =IF(COUNTIFS('02_MASTER'!$B:$B,"DK.PAY.WLT.OWN",'02_MASTER'!$E:$E,2019)=0,"",SUMIFS('02_MASTER'!$F:$F,'02_MASTER'!$B:$B,"DK.PAY.WLT.OWN",'02_MASTER'!$E:$E,2019))
A19: 2023 | B19: =IF(COUNTIFS('02_MASTER'!$B:$B,"DK.PAY.WLT.OWN",'02_MASTER'!$E:$E,2023)=0,"",SUMIFS('02_MASTER'!$F:$F,'02_MASTER'!$B:$B,"DK.PAY.WLT.OWN",'02_MASTER'!$E:$E,2023))
A20: 2025 | B20: =IF(COUNTIFS('02_MASTER'!$B:$B,"DK.PAY.WLT.OWN",'02_MASTER'!$E:$E,2025)=0,"",SUMIFS('02_MASTER'!$F:$F,'02_MASTER'!$B:$B,"DK.PAY.WLT.OWN",'02_MASTER'!$E:$E,2025))
A23: POLICY EVENTS ON THIS SERIES
A24: date | B24: precision | C24: instrument | D24: citation | E24: source
A25: 2022-07-01 | B25: day | C25: Kontantreglen amended | D25: Lov om betalinger, ss 81 | E25: RI2
A27: Source: Danmarks Nationalbank, Danskernes betalingsvaner (NB1). Panel B sums to 95%, not 100%: the residual is other digital instruments (chiefly account transfers and non-card mobile payments). Wallet payments ARE card payments settled through a phone, so the wallet and physical-card rows must not be added to produce a 'card' total. The memo series is excluded from both panels because its denominator is % of citizens, not % of payments. Physical card and wallet shares are observed in 2025 only, so no time series is drawn for them - a two-point line through an unobserved middle would assert a path the data does not contain.

Sheet F3_ESALES
A1: Figure 3 - E-sales as a share of enterprise turnover, DK vs EU
A2: Tests the 'enterprise plateau' claim: intensity nearly doubled.
E3: E-sales as % of enterprise turnover, DK vs EU-27
A4: year | B4: Denmark | C4: EU-27 | E4: Denmark in blue; the EU average in grey.
A5: 2014 | B5: =IF(COUNTIFS('02_MASTER'!$B:$B,"DK.ECM.ENT.TRN",'02_MASTER'!$E:$E,2014)=0,"",SUMIFS('02_MASTER'!$F:$F,'02_MASTER'!$B:$B,"DK.ECM.ENT.TRN",'02_MASTER'!$E:$E,2014)) | C5: =IF(COUNTIFS('02_MASTER'!$B:$B,"EU.ECM.ENT.TRN",'02_MASTER'!$E:$E,2014)=0,"",SUMIFS('02_MASTER'!$F:$F,'02_MASTER'!$B:$B,"EU.ECM.ENT.TRN",'02_MASTER'!$E:$E,2014))
A6: 2024 | B6: =IF(COUNTIFS('02_MASTER'!$B:$B,"DK.ECM.ENT.TRN",'02_MASTER'!$E:$E,2024)=0,"",SUMIFS('02_MASTER'!$F:$F,'02_MASTER'!$B:$B,"DK.ECM.ENT.TRN",'02_MASTER'!$E:$E,2024)) | C6: =IF(COUNTIFS('02_MASTER'!$B:$B,"EU.ECM.ENT.TRN",'02_MASTER'!$E:$E,2024)=0,"",SUMIFS('02_MASTER'!$F:$F,'02_MASTER'!$B:$B,"EU.ECM.ENT.TRN",'02_MASTER'!$E:$E,2024))
A9: CONTEXT - breadth vs intensity, 2024
A10: measure | B10: Denmark | C10: EU / leader
A11: Enterprises making e-sales (%) | B11: =IF(COUNTIFS('02_MASTER'!$B:$B,"DK.ECM.ENT.SHR",'02_MASTER'!$E:$E,2024)=0,"",SUMIFS('02_MASTER'!$F:$F,'02_MASTER'!$B:$B,"DK.ECM.ENT.SHR",'02_MASTER'!$E:$E,2024)) | C11: Lithuania 43.03 (highest)
A12: E-sales share of turnover (%) | B12: =IF(COUNTIFS('02_MASTER'!$B:$B,"DK.ECM.ENT.TRN",'02_MASTER'!$E:$E,2024)=0,"",SUMIFS('02_MASTER'!$F:$F,'02_MASTER'!$B:$B,"DK.ECM.ENT.TRN",'02_MASTER'!$E:$E,2024)) | C12: Ireland 38.25 (highest)
A13: EU average, e-sales share of turnover (%) | B13: =IF(COUNTIFS('02_MASTER'!$B:$B,"EU.ECM.ENT.TRN",'02_MASTER'!$E:$E,2024)=0,"",SUMIFS('02_MASTER'!$F:$F,'02_MASTER'!$B:$B,"EU.ECM.ENT.TRN",'02_MASTER'!$E:$E,2024))
A16: POLICY EVENTS ON THIS SERIES
A17: date | B17: precision | C17: instrument | D17: citation | E17: source
A18: 2013-01-01 | B18: year | C18: Digital Post becomes mandatory for businesses | D18: Lov om Offentlig Digital Post | E18: DG4
A20: Source: Eurostat (ES5). Reading: Denmark's e-sales share of turnover rose from 17.05% to 33.31% while the EU average moved from 16.43% to 19.49%. Breadth of adoption is flat at roughly 38% of enterprises; intensity nearly doubled. The growth came from incumbents selling more online, not from new firms entering.

Sheet F4_EXCLUSION
A1: Figure 4 - Five measures of digital exclusion in Denmark
A2: Same phenomenon, five definitions. The spread is the finding.
F3: Measures of digital exclusion, Denmark
A4: measure | B4: % | C4: definition basis | D4: source | F4: Five definitions of the same phenomenon; they are nested, not contradictory.
A5: Formally exempt from Digital Post (Q1 2026) | B5: =IF(COUNTIFS('02_MASTER'!$B:$B,"DK.DGP.EXMP",'02_MASTER'!$E:$E,2026)=0,"",SUMIFS('02_MASTER'!$F:$F,'02_MASTER'!$B:$B,"DK.DGP.EXMP",'02_MASTER'!$E:$E,2026)) | C5: administrative status | D5: DG1
A6: Do not use digital public services at all | B6: =IF(COUNTIFS('02_MASTER'!$B:$B,"DK.DGX.NOUSE",'02_MASTER'!$E:$E,2026)=0,"",SUMIFS('02_MASTER'!$F:$F,'02_MASTER'!$B:$B,"DK.DGX.NOUSE",'02_MASTER'!$E:$E,2026)) | C6: self-reported non-use | D6: EC1
A7: Face difficulties using digital public services | B7: =IF(COUNTIFS('02_MASTER'!$B:$B,"DK.DGX.DIFF",'02_MASTER'!$E:$E,2026)=0,"",SUMIFS('02_MASTER'!$F:$F,'02_MASTER'!$B:$B,"DK.DGX.DIFF",'02_MASTER'!$E:$E,2026)) | C7: capability estimate | D7: EC1
A8: 'Digitally disadvantaged' - lower bound | B8: =IF(COUNTIFS('02_MASTER'!$B:$B,"DK.DGX.DISADV.LO",'02_MASTER'!$E:$E,2025)=0,"",SUMIFS('02_MASTER'!$F:$F,'02_MASTER'!$B:$B,"DK.DGX.DISADV.LO",'02_MASTER'!$E:$E,2025)) | C8: capability estimate (range) | D8: DG2
A9: 'Digitally disadvantaged' - upper bound | B9: =IF(COUNTIFS('02_MASTER'!$B:$B,"DK.DGX.DISADV.HI",'02_MASTER'!$E:$E,2025)=0,"",SUMIFS('02_MASTER'!$F:$F,'02_MASTER'!$B:$B,"DK.DGX.DISADV.HI",'02_MASTER'!$E:$E,2025)) | C9: capability estimate (range) | D9: DG2
A10: 'Digitally disadvantaged' - Justitia | B10: =IF(COUNTIFS('02_MASTER'!$B:$B,"DK.DGX.JUST",'02_MASTER'!$E:$E,2022)=0,"",SUMIFS('02_MASTER'!$F:$F,'02_MASTER'!$B:$B,"DK.DGX.JUST",'02_MASTER'!$E:$E,2022)) | C10: broadest definition | D10: JU1
A12: AGE GRADIENT IN FORMAL EXEMPTION (2022)
A13: age group | B13: exempt (%)
A14: Age 75-84 | B14: =IF(COUNTIFS('02_MASTER'!$B:$B,"DK.DGP.EXMP.7584",'02_MASTER'!$E:$E,2022)=0,"",SUMIFS('02_MASTER'!$F:$F,'02_MASTER'!$B:$B,"DK.DGP.EXMP.7584",'02_MASTER'!$E:$E,2022))
A15: Age 85+ | B15: =IF(COUNTIFS('02_MASTER'!$B:$B,"DK.DGP.EXMP.85P",'02_MASTER'!$E:$E,2022)=0,"",SUMIFS('02_MASTER'!$F:$F,'02_MASTER'!$B:$B,"DK.DGP.EXMP.85P",'02_MASTER'!$E:$E,2022))
A17: HEADCOUNTS, NOT SHARES
A18: quantity | B18: persons | C18: basis
A19: Citizens formally exempt, Q1 2026 | B19: =IF(COUNTIFS('02_MASTER'!$B:$B,"DK.DGP.EXMP.N",'02_MASTER'!$E:$E,2026)=0,"",SUMIFS('02_MASTER'!$F:$F,'02_MASTER'!$B:$B,"DK.DGP.EXMP.N",'02_MASTER'!$E:$E,2026)) | C19: Reported directly by the Agency for Digital Government (DG1).
A20: Citizens formally exempt, April 2025 | B20: =IF(COUNTIFS('02_MASTER'!$B:$B,"DK.DGP.EXMP.N",'02_MASTER'!$E:$E,2025)=0,"",SUMIFS('02_MASTER'!$F:$F,'02_MASTER'!$B:$B,"DK.DGP.EXMP.N",'02_MASTER'!$E:$E,2025)) | C20: Reported as approximately 256,000 (DG1).
A21: Implied population aged 15+ | B21: =IF(COUNTIFS('02_MASTER'!$B:$B,"DK.DGP.EXMP.N",'02_MASTER'!$E:$E,2026)=0,"",SUMIFS('02_MASTER'!$F:$F,'02_MASTER'!$B:$B,"DK.DGP.EXMP.N",'02_MASTER'!$E:$E,2026))/(IF(COUNTIFS('02_MASTER'!$B:$B,"DK.DGP.EXMP",'02_MASTER'!$E:$E,2026)=0,"",SUMIFS('02_MASTER'!$F:$F,'02_MASTER'!$B:$B,"DK.DGP.EXMP",'02_MASTER'!$E:$E,2026))/100) | C21: DERIVED, not retrieved: the exempt headcount divided by the exemption rate. Used only to convert the capability shares below into orders of magnitude. A published 15+ population figure was not verifiable in this session; see 06_RETAIL_GAP.
A22: Implied persons who do not use digital public services at all | B22: =(IF(COUNTIFS('02_MASTER'!$B:$B,"DK.DGX.NOUSE",'02_MASTER'!$E:$E,2026)=0,"",SUMIFS('02_MASTER'!$F:$F,'02_MASTER'!$B:$B,"DK.DGX.NOUSE",'02_MASTER'!$E:$E,2026))/100)*(IF(COUNTIFS('02_MASTER'!$B:$B,"DK.DGP.EXMP.N",'02_MASTER'!$E:$E,2026)=0,"",SUMIFS('02_MASTER'!$F:$F,'02_MASTER'!$B:$B,"DK.DGP.EXMP.N",'02_MASTER'!$E:$E,2026))/(IF(COUNTIFS('02_MASTER'!$B:$B,"DK.DGP.EXMP",'02_MASTER'!$E:$E,2026)=0,"",SUMIFS('02_MASTER'!$F:$F,'02_MASTER'!$B:$B,"DK.DGP.EXMP",'02_MASTER'!$E:$E,2026))/100)) | C22: ORDER OF MAGNITUDE ONLY. Applies a share measured on 'the population' to a 15+ base; the denominators are not identical.
A23: Implied persons facing difficulty with digital public services | B23: =(IF(COUNTIFS('02_MASTER'!$B:$B,"DK.DGX.DIFF",'02_MASTER'!$E:$E,2026)=0,"",SUMIFS('02_MASTER'!$F:$F,'02_MASTER'!$B:$B,"DK.DGX.DIFF",'02_MASTER'!$E:$E,2026))/100)*(IF(COUNTIFS('02_MASTER'!$B:$B,"DK.DGP.EXMP.N",'02_MASTER'!$E:$E,2026)=0,"",SUMIFS('02_MASTER'!$F:$F,'02_MASTER'!$B:$B,"DK.DGP.EXMP.N",'02_MASTER'!$E:$E,2026))/(IF(COUNTIFS('02_MASTER'!$B:$B,"DK.DGP.EXMP",'02_MASTER'!$E:$E,2026)=0,"",SUMIFS('02_MASTER'!$F:$F,'02_MASTER'!$B:$B,"DK.DGP.EXMP",'02_MASTER'!$E:$E,2026))/100)) | C23: ORDER OF MAGNITUDE ONLY, same caveat.
A25: POLICY EVENTS ON THIS SERIES
A26: date | B26: precision | C26: instrument | D26: citation | E26: source
A27: 2012-06-11 | B27: day | C27: Lov om Offentlig Digital Post adopted | D27: LOV nr 528 af 11/06/2012 | E27: RI1
A28: 2014-11-01 | B28: day | C28: Digital Post becomes mandatory for citizens aged 15+ | D28: Lov om Offentlig Digital Post | E28: DG4
A30: Sources: DG1, DG2, EC1, JU1. Reading: the measures are nested rather than contradictory. Formal exemption (4.7%) is an administrative status; the capability measures are three to five times larger. The statutory exemption regime therefore reaches only a minority of the citizens the state's own agency counts as struggling. Which measure is chosen determines the conclusion - so the choice must be argued, not assumed.

Sheet F5_EU27
A1: Figure 5 - Individuals who bought online, 2024
A2: All 27 member states and the EU-27 aggregate, ranked. Denominator: % of internet users.
E3: Individuals who bought online, 2024
A4: country | B4: % | C4: series_code | E4: Denmark in blue, EU-27 aggregate in navy, member states in grey. Ranked descending.
A5: Ireland | B5: =IF(COUNTIFS('02_MASTER'!$B:$B,"IE.ECM.IND.BUY",'02_MASTER'!$E:$E,2024)=0,"",SUMIFS('02_MASTER'!$F:$F,'02_MASTER'!$B:$B,"IE.ECM.IND.BUY",'02_MASTER'!$E:$E,2024)) | C5: IE.ECM.IND.BUY
A6: Netherlands | B6: =IF(COUNTIFS('02_MASTER'!$B:$B,"NL.ECM.IND.BUY",'02_MASTER'!$E:$E,2024)=0,"",SUMIFS('02_MASTER'!$F:$F,'02_MASTER'!$B:$B,"NL.ECM.IND.BUY",'02_MASTER'!$E:$E,2024)) | C6: NL.ECM.IND.BUY
A7: Denmark | B7: =IF(COUNTIFS('02_MASTER'!$B:$B,"DK.ECM.IND.BUY",'02_MASTER'!$E:$E,2024)=0,"",SUMIFS('02_MASTER'!$F:$F,'02_MASTER'!$B:$B,"DK.ECM.IND.BUY",'02_MASTER'!$E:$E,2024)) | C7: DK.ECM.IND.BUY
A8: Sweden | B8: =IF(COUNTIFS('02_MASTER'!$B:$B,"SE.ECM.IND.BUY",'02_MASTER'!$E:$E,2024)=0,"",SUMIFS('02_MASTER'!$F:$F,'02_MASTER'!$B:$B,"SE.ECM.IND.BUY",'02_MASTER'!$E:$E,2024)) | C8: SE.ECM.IND.BUY
A9: Czechia | B9: =IF(COUNTIFS('02_MASTER'!$B:$B,"CZ.ECM.IND.BUY",'02_MASTER'!$E:$E,2024)=0,"",SUMIFS('02_MASTER'!$F:$F,'02_MASTER'!$B:$B,"CZ.ECM.IND.BUY",'02_MASTER'!$E:$E,2024)) | C9: CZ.ECM.IND.BUY
A10: Slovakia | B10: =IF(COUNTIFS('02_MASTER'!$B:$B,"SK.ECM.IND.BUY",'02_MASTER'!$E:$E,2024)=0,"",SUMIFS('02_MASTER'!$F:$F,'02_MASTER'!$B:$B,"SK.ECM.IND.BUY",'02_MASTER'!$E:$E,2024)) | C10: SK.ECM.IND.BUY
A11: France | B11: =IF(COUNTIFS('02_MASTER'!$B:$B,"FR.ECM.IND.BUY",'02_MASTER'!$E:$E,2024)=0,"",SUMIFS('02_MASTER'!$F:$F,'02_MASTER'!$B:$B,"FR.ECM.IND.BUY",'02_MASTER'!$E:$E,2024)) | C11: FR.ECM.IND.BUY
A12: Germany | B12: =IF(COUNTIFS('02_MASTER'!$B:$B,"DE.ECM.IND.BUY",'02_MASTER'!$E:$E,2024)=0,"",SUMIFS('02_MASTER'!$F:$F,'02_MASTER'!$B:$B,"DE.ECM.IND.BUY",'02_MASTER'!$E:$E,2024)) | C12: DE.ECM.IND.BUY
A13: Luxembourg | B13: =IF(COUNTIFS('02_MASTER'!$B:$B,"LU.ECM.IND.BUY",'02_MASTER'!$E:$E,2024)=0,"",SUMIFS('02_MASTER'!$F:$F,'02_MASTER'!$B:$B,"LU.ECM.IND.BUY",'02_MASTER'!$E:$E,2024)) | C13: LU.ECM.IND.BUY
A14: Finland | B14: =IF(COUNTIFS('02_MASTER'!$B:$B,"FI.ECM.IND.BUY",'02_MASTER'!$E:$E,2024)=0,"",SUMIFS('02_MASTER'!$F:$F,'02_MASTER'!$B:$B,"FI.ECM.IND.BUY",'02_MASTER'!$E:$E,2024)) | C14: FI.ECM.IND.BUY
A15: Belgium | B15: =IF(COUNTIFS('02_MASTER'!$B:$B,"BE.ECM.IND.BUY",'02_MASTER'!$E:$E,2024)=0,"",SUMIFS('02_MASTER'!$F:$F,'02_MASTER'!$B:$B,"BE.ECM.IND.BUY",'02_MASTER'!$E:$E,2024)) | C15: BE.ECM.IND.BUY
A16: Hungary | B16: =IF(COUNTIFS('02_MASTER'!$B:$B,"HU.ECM.IND.BUY",'02_MASTER'!$E:$E,2024)=0,"",SUMIFS('02_MASTER'!$F:$F,'02_MASTER'!$B:$B,"HU.ECM.IND.BUY",'02_MASTER'!$E:$E,2024)) | C16: HU.ECM.IND.BUY
A17: Estonia | B17: =IF(COUNTIFS('02_MASTER'!$B:$B,"EE.ECM.IND.BUY",'02_MASTER'!$E:$E,2024)=0,"",SUMIFS('02_MASTER'!$F:$F,'02_MASTER'!$B:$B,"EE.ECM.IND.BUY",'02_MASTER'!$E:$E,2024)) | C17: EE.ECM.IND.BUY
A18: EU-27 average | B18: =IF(COUNTIFS('02_MASTER'!$B:$B,"EU.ECM.IND.BUY",'02_MASTER'!$E:$E,2024)=0,"",SUMIFS('02_MASTER'!$F:$F,'02_MASTER'!$B:$B,"EU.ECM.IND.BUY",'02_MASTER'!$E:$E,2024)) | C18: EU.ECM.IND.BUY
A19: Poland | B19: =IF(COUNTIFS('02_MASTER'!$B:$B,"PL.ECM.IND.BUY",'02_MASTER'!$E:$E,2024)=0,"",SUMIFS('02_MASTER'!$F:$F,'02_MASTER'!$B:$B,"PL.ECM.IND.BUY",'02_MASTER'!$E:$E,2024)) | C19: PL.ECM.IND.BUY
A20: Greece | B20: =IF(COUNTIFS('02_MASTER'!$B:$B,"EL.ECM.IND.BUY",'02_MASTER'!$E:$E,2024)=0,"",SUMIFS('02_MASTER'!$F:$F,'02_MASTER'!$B:$B,"EL.ECM.IND.BUY",'02_MASTER'!$E:$E,2024)) | C20: EL.ECM.IND.BUY
A21: Austria | B21: =IF(COUNTIFS('02_MASTER'!$B:$B,"AT.ECM.IND.BUY",'02_MASTER'!$E:$E,2024)=0,"",SUMIFS('02_MASTER'!$F:$F,'02_MASTER'!$B:$B,"AT.ECM.IND.BUY",'02_MASTER'!$E:$E,2024)) | C21: AT.ECM.IND.BUY
A22: Malta | B22: =IF(COUNTIFS('02_MASTER'!$B:$B,"MT.ECM.IND.BUY",'02_MASTER'!$E:$E,2024)=0,"",SUMIFS('02_MASTER'!$F:$F,'02_MASTER'!$B:$B,"MT.ECM.IND.BUY",'02_MASTER'!$E:$E,2024)) | C22: MT.ECM.IND.BUY
A23: Slovenia | B23: =IF(COUNTIFS('02_MASTER'!$B:$B,"SI.ECM.IND.BUY",'02_MASTER'!$E:$E,2024)=0,"",SUMIFS('02_MASTER'!$F:$F,'02_MASTER'!$B:$B,"SI.ECM.IND.BUY",'02_MASTER'!$E:$E,2024)) | C23: SI.ECM.IND.BUY
A24: Lithuania | B24: =IF(COUNTIFS('02_MASTER'!$B:$B,"LT.ECM.IND.BUY",'02_MASTER'!$E:$E,2024)=0,"",SUMIFS('02_MASTER'!$F:$F,'02_MASTER'!$B:$B,"LT.ECM.IND.BUY",'02_MASTER'!$E:$E,2024)) | C24: LT.ECM.IND.BUY
A25: Spain | B25: =IF(COUNTIFS('02_MASTER'!$B:$B,"ES.ECM.IND.BUY",'02_MASTER'!$E:$E,2024)=0,"",SUMIFS('02_MASTER'!$F:$F,'02_MASTER'!$B:$B,"ES.ECM.IND.BUY",'02_MASTER'!$E:$E,2024)) | C25: ES.ECM.IND.BUY
A26: Croatia | B26: =IF(COUNTIFS('02_MASTER'!$B:$B,"HR.ECM.IND.BUY",'02_MASTER'!$E:$E,2024)=0,"",SUMIFS('02_MASTER'!$F:$F,'02_MASTER'!$B:$B,"HR.ECM.IND.BUY",'02_MASTER'!$E:$E,2024)) | C26: HR.ECM.IND.BUY
A27: Latvia | B27: =IF(COUNTIFS('02_MASTER'!$B:$B,"LV.ECM.IND.BUY",'02_MASTER'!$E:$E,2024)=0,"",SUMIFS('02_MASTER'!$F:$F,'02_MASTER'!$B:$B,"LV.ECM.IND.BUY",'02_MASTER'!$E:$E,2024)) | C27: LV.ECM.IND.BUY
A28: Cyprus | B28: =IF(COUNTIFS('02_MASTER'!$B:$B,"CY.ECM.IND.BUY",'02_MASTER'!$E:$E,2024)=0,"",SUMIFS('02_MASTER'!$F:$F,'02_MASTER'!$B:$B,"CY.ECM.IND.BUY",'02_MASTER'!$E:$E,2024)) | C28: CY.ECM.IND.BUY
A29: Portugal | B29: =IF(COUNTIFS('02_MASTER'!$B:$B,"PT.ECM.IND.BUY",'02_MASTER'!$E:$E,2024)=0,"",SUMIFS('02_MASTER'!$F:$F,'02_MASTER'!$B:$B,"PT.ECM.IND.BUY",'02_MASTER'!$E:$E,2024)) | C29: PT.ECM.IND.BUY
A30: Romania | B30: =IF(COUNTIFS('02_MASTER'!$B:$B,"RO.ECM.IND.BUY",'02_MASTER'!$E:$E,2024)=0,"",SUMIFS('02_MASTER'!$F:$F,'02_MASTER'!$B:$B,"RO.ECM.IND.BUY",'02_MASTER'!$E:$E,2024)) | C30: RO.ECM.IND.BUY
A31: Italy | B31: =IF(COUNTIFS('02_MASTER'!$B:$B,"IT.ECM.IND.BUY",'02_MASTER'!$E:$E,2024)=0,"",SUMIFS('02_MASTER'!$F:$F,'02_MASTER'!$B:$B,"IT.ECM.IND.BUY",'02_MASTER'!$E:$E,2024)) | C31: IT.ECM.IND.BUY
A32: Bulgaria | B32: =IF(COUNTIFS('02_MASTER'!$B:$B,"BG.ECM.IND.BUY",'02_MASTER'!$E:$E,2024)=0,"",SUMIFS('02_MASTER'!$F:$F,'02_MASTER'!$B:$B,"BG.ECM.IND.BUY",'02_MASTER'!$E:$E,2024)) | C32: BG.ECM.IND.BUY
A34: Source: Eurostat isoc_ec_ib20, complete databrowser extract for 2024 (ES7), unrounded. This replaces an earlier 8-country version built from rounded press-release figures; on those the Italian and Romanian values both read 60% and appeared tied, while unrounded Italy is second lowest at 59.60 and Romania is above it at 59.73. Bulgaria remains the lowest of the 27 at 57.18. The ranking above is computed from the data at build time, so it cannot fall out of step with 02_MASTER. Denominator is % of internet users, not % of individuals - see 04_DEFINITIONS.

Sheet F6_ADOPT_BENEFIT
A1: Figure 6 - Does more digital adoption mean more economic activity?
A2: EU cross-section, 2024. X = consumer adoption. Y = share of enterprise turnover from e-sales.
F3: Digital adoption and e-commerce turnover, EU 2024
A4: country | B4: code | C4: X: individuals buying online (%) | D4: Y: e-sales share of turnover (%) | F4: One point per member state with both measures. Fitted by ordinary least squares; see the statistics below.
A5: Austria | B5: AT | C5: =IF(COUNTIFS('02_MASTER'!$B:$B,"AT.ECM.IND.BUY",'02_MASTER'!$E:$E,2024)=0,"",SUMIFS('02_MASTER'!$F:$F,'02_MASTER'!$B:$B,"AT.ECM.IND.BUY",'02_MASTER'!$E:$E,2024)) | D5: =IF(COUNTIFS('02_MASTER'!$B:$B,"AT.ECM.ENT.TRN",'02_MASTER'!$E:$E,2024)=0,"",SUMIFS('02_MASTER'!$F:$F,'02_MASTER'!$B:$B,"AT.ECM.ENT.TRN",'02_MASTER'!$E:$E,2024))
A6: Belgium | B6: BE | C6: =IF(COUNTIFS('02_MASTER'!$B:$B,"BE.ECM.IND.BUY",'02_MASTER'!$E:$E,2024)=0,"",SUMIFS('02_MASTER'!$F:$F,'02_MASTER'!$B:$B,"BE.ECM.IND.BUY",'02_MASTER'!$E:$E,2024)) | D6: =IF(COUNTIFS('02_MASTER'!$B:$B,"BE.ECM.ENT.TRN",'02_MASTER'!$E:$E,2024)=0,"",SUMIFS('02_MASTER'!$F:$F,'02_MASTER'!$B:$B,"BE.ECM.ENT.TRN",'02_MASTER'!$E:$E,2024))
A7: Bulgaria | B7: BG | C7: =IF(COUNTIFS('02_MASTER'!$B:$B,"BG.ECM.IND.BUY",'02_MASTER'!$E:$E,2024)=0,"",SUMIFS('02_MASTER'!$F:$F,'02_MASTER'!$B:$B,"BG.ECM.IND.BUY",'02_MASTER'!$E:$E,2024)) | D7: =IF(COUNTIFS('02_MASTER'!$B:$B,"BG.ECM.ENT.TRN",'02_MASTER'!$E:$E,2024)=0,"",SUMIFS('02_MASTER'!$F:$F,'02_MASTER'!$B:$B,"BG.ECM.ENT.TRN",'02_MASTER'!$E:$E,2024))
A8: Cyprus | B8: CY | C8: =IF(COUNTIFS('02_MASTER'!$B:$B,"CY.ECM.IND.BUY",'02_MASTER'!$E:$E,2024)=0,"",SUMIFS('02_MASTER'!$F:$F,'02_MASTER'!$B:$B,"CY.ECM.IND.BUY",'02_MASTER'!$E:$E,2024)) | D8: =IF(COUNTIFS('02_MASTER'!$B:$B,"CY.ECM.ENT.TRN",'02_MASTER'!$E:$E,2024)=0,"",SUMIFS('02_MASTER'!$F:$F,'02_MASTER'!$B:$B,"CY.ECM.ENT.TRN",'02_MASTER'!$E:$E,2024))
A9: Czechia | B9: CZ | C9: =IF(COUNTIFS('02_MASTER'!$B:$B,"CZ.ECM.IND.BUY",'02_MASTER'!$E:$E,2024)=0,"",SUMIFS('02_MASTER'!$F:$F,'02_MASTER'!$B:$B,"CZ.ECM.IND.BUY",'02_MASTER'!$E:$E,2024)) | D9: =IF(COUNTIFS('02_MASTER'!$B:$B,"CZ.ECM.ENT.TRN",'02_MASTER'!$E:$E,2024)=0,"",SUMIFS('02_MASTER'!$F:$F,'02_MASTER'!$B:$B,"CZ.ECM.ENT.TRN",'02_MASTER'!$E:$E,2024))
A10: Germany | B10: DE | C10: =IF(COUNTIFS('02_MASTER'!$B:$B,"DE.ECM.IND.BUY",'02_MASTER'!$E:$E,2024)=0,"",SUMIFS('02_MASTER'!$F:$F,'02_MASTER'!$B:$B,"DE.ECM.IND.BUY",'02_MASTER'!$E:$E,2024)) | D10: =IF(COUNTIFS('02_MASTER'!$B:$B,"DE.ECM.ENT.TRN",'02_MASTER'!$E:$E,2024)=0,"",SUMIFS('02_MASTER'!$F:$F,'02_MASTER'!$B:$B,"DE.ECM.ENT.TRN",'02_MASTER'!$E:$E,2024))
A11: Denmark | B11: DK | C11: =IF(COUNTIFS('02_MASTER'!$B:$B,"DK.ECM.IND.BUY",'02_MASTER'!$E:$E,2024)=0,"",SUMIFS('02_MASTER'!$F:$F,'02_MASTER'!$B:$B,"DK.ECM.IND.BUY",'02_MASTER'!$E:$E,2024)) | D11: =IF(COUNTIFS('02_MASTER'!$B:$B,"DK.ECM.ENT.TRN",'02_MASTER'!$E:$E,2024)=0,"",SUMIFS('02_MASTER'!$F:$F,'02_MASTER'!$B:$B,"DK.ECM.ENT.TRN",'02_MASTER'!$E:$E,2024))
A12: Spain | B12: ES | C12: =IF(COUNTIFS('02_MASTER'!$B:$B,"ES.ECM.IND.BUY",'02_MASTER'!$E:$E,2024)=0,"",SUMIFS('02_MASTER'!$F:$F,'02_MASTER'!$B:$B,"ES.ECM.IND.BUY",'02_MASTER'!$E:$E,2024)) | D12: =IF(COUNTIFS('02_MASTER'!$B:$B,"ES.ECM.ENT.TRN",'02_MASTER'!$E:$E,2024)=0,"",SUMIFS('02_MASTER'!$F:$F,'02_MASTER'!$B:$B,"ES.ECM.ENT.TRN",'02_MASTER'!$E:$E,2024))
A13: France | B13: FR | C13: =IF(COUNTIFS('02_MASTER'!$B:$B,"FR.ECM.IND.BUY",'02_MASTER'!$E:$E,2024)=0,"",SUMIFS('02_MASTER'!$F:$F,'02_MASTER'!$B:$B,"FR.ECM.IND.BUY",'02_MASTER'!$E:$E,2024)) | D13: =IF(COUNTIFS('02_MASTER'!$B:$B,"FR.ECM.ENT.TRN",'02_MASTER'!$E:$E,2024)=0,"",SUMIFS('02_MASTER'!$F:$F,'02_MASTER'!$B:$B,"FR.ECM.ENT.TRN",'02_MASTER'!$E:$E,2024))
A14: Croatia | B14: HR | C14: =IF(COUNTIFS('02_MASTER'!$B:$B,"HR.ECM.IND.BUY",'02_MASTER'!$E:$E,2024)=0,"",SUMIFS('02_MASTER'!$F:$F,'02_MASTER'!$B:$B,"HR.ECM.IND.BUY",'02_MASTER'!$E:$E,2024)) | D14: =IF(COUNTIFS('02_MASTER'!$B:$B,"HR.ECM.ENT.TRN",'02_MASTER'!$E:$E,2024)=0,"",SUMIFS('02_MASTER'!$F:$F,'02_MASTER'!$B:$B,"HR.ECM.ENT.TRN",'02_MASTER'!$E:$E,2024))
A15: Hungary | B15: HU | C15: =IF(COUNTIFS('02_MASTER'!$B:$B,"HU.ECM.IND.BUY",'02_MASTER'!$E:$E,2024)=0,"",SUMIFS('02_MASTER'!$F:$F,'02_MASTER'!$B:$B,"HU.ECM.IND.BUY",'02_MASTER'!$E:$E,2024)) | D15: =IF(COUNTIFS('02_MASTER'!$B:$B,"HU.ECM.ENT.TRN",'02_MASTER'!$E:$E,2024)=0,"",SUMIFS('02_MASTER'!$F:$F,'02_MASTER'!$B:$B,"HU.ECM.ENT.TRN",'02_MASTER'!$E:$E,2024))
A16: Ireland | B16: IE | C16: =IF(COUNTIFS('02_MASTER'!$B:$B,"IE.ECM.IND.BUY",'02_MASTER'!$E:$E,2024)=0,"",SUMIFS('02_MASTER'!$F:$F,'02_MASTER'!$B:$B,"IE.ECM.IND.BUY",'02_MASTER'!$E:$E,2024)) | D16: =IF(COUNTIFS('02_MASTER'!$B:$B,"IE.ECM.ENT.TRN",'02_MASTER'!$E:$E,2024)=0,"",SUMIFS('02_MASTER'!$F:$F,'02_MASTER'!$B:$B,"IE.ECM.ENT.TRN",'02_MASTER'!$E:$E,2024))
A17: Italy | B17: IT | C17: =IF(COUNTIFS('02_MASTER'!$B:$B,"IT.ECM.IND.BUY",'02_MASTER'!$E:$E,2024)=0,"",SUMIFS('02_MASTER'!$F:$F,'02_MASTER'!$B:$B,"IT.ECM.IND.BUY",'02_MASTER'!$E:$E,2024)) | D17: =IF(COUNTIFS('02_MASTER'!$B:$B,"IT.ECM.ENT.TRN",'02_MASTER'!$E:$E,2024)=0,"",SUMIFS('02_MASTER'!$F:$F,'02_MASTER'!$B:$B,"IT.ECM.ENT.TRN",'02_MASTER'!$E:$E,2024))
A18: Luxembourg | B18: LU | C18: =IF(COUNTIFS('02_MASTER'!$B:$B,"LU.ECM.IND.BUY",'02_MASTER'!$E:$E,2024)=0,"",SUMIFS('02_MASTER'!$F:$F,'02_MASTER'!$B:$B,"LU.ECM.IND.BUY",'02_MASTER'!$E:$E,2024)) | D18: =IF(COUNTIFS('02_MASTER'!$B:$B,"LU.ECM.ENT.TRN",'02_MASTER'!$E:$E,2024)=0,"",SUMIFS('02_MASTER'!$F:$F,'02_MASTER'!$B:$B,"LU.ECM.ENT.TRN",'02_MASTER'!$E:$E,2024))
A19: Malta | B19: MT | C19: =IF(COUNTIFS('02_MASTER'!$B:$B,"MT.ECM.IND.BUY",'02_MASTER'!$E:$E,2024)=0,"",SUMIFS('02_MASTER'!$F:$F,'02_MASTER'!$B:$B,"MT.ECM.IND.BUY",'02_MASTER'!$E:$E,2024)) | D19: =IF(COUNTIFS('02_MASTER'!$B:$B,"MT.ECM.ENT.TRN",'02_MASTER'!$E:$E,2024)=0,"",SUMIFS('02_MASTER'!$F:$F,'02_MASTER'!$B:$B,"MT.ECM.ENT.TRN",'02_MASTER'!$E:$E,2024))
A20: Poland | B20: PL | C20: =IF(COUNTIFS('02_MASTER'!$B:$B,"PL.ECM.IND.BUY",'02_MASTER'!$E:$E,2024)=0,"",SUMIFS('02_MASTER'!$F:$F,'02_MASTER'!$B:$B,"PL.ECM.IND.BUY",'02_MASTER'!$E:$E,2024)) | D20: =IF(COUNTIFS('02_MASTER'!$B:$B,"PL.ECM.ENT.TRN",'02_MASTER'!$E:$E,2024)=0,"",SUMIFS('02_MASTER'!$F:$F,'02_MASTER'!$B:$B,"PL.ECM.ENT.TRN",'02_MASTER'!$E:$E,2024))
